Workbook

Sheet Amazon.com _ gaming laptops_dat
A1: Title | B1: Brand Name | C1: Laptop Model | D1: Laptop Category | E1: Screen Size (Inches) | F1: Processor | G1: RAM (GB) | H1: Storage (GB) | I1: Operating System | J1: Graphics | K1: GPU Model | L1: Display Resolution | M1: Display Type | N1: Refresh Rate (Hz) | O1: CPU Speed | P1: Color | Q1: Features | R1: Connectivity | S1: Rating(0-5) | T1: Reviewers | U1: Discounted Price (PKR) | V1: Full Price (PKR) | W1: Discount Percentage(%) | X1: Discount Status | Y1: Delivery Charges (PKR) | Z1: Minimum Delivery Date | AB1: image url | AC1: Title_URL
A2: ASUS ROG Strix G16 (2025) Gaming Laptop, 16" FHD+ 16:10 165Hz/3ms, NVIDIA® GeForce RTX™ 5060, Intel® Core™ i7 Processor 14650HX, 16GB DDR5, 1TB Gen 4 SSD, Wi-Fi 7, Windows 11 Home, G615JMR-AS74 | B2: ASUS | C2: ROG Strix G16 | D2: =IF(OR(ISNUMBER(SEARCH("charger",A2)),ISNUMBER(SEARCH("cable",A2)),ISNUMBER(SEARCH("adapter",A2)),ISNUMBER(SEARCH("dock",A2)),ISNUMBER(SEARCH("replacement",A2))),"Accessory / Other",IF(OR(J2="Dedicated",ISNUMBER(SEARCH("rtx",J2&" "&K2)),ISNUMBER(SEARCH("gtx",J2&" "&K2)),ISNUMBER(SEARCH("rx 5",J2&" "&K2)),ISNUMBER(SEARCH("rx 6",J2&" "&K2)),ISNUMBER(SEARCH("rx 7",J2&" "&K2)),ISNUMBER(SEARCH("rx 8",J2&" "&K2)),ISNUMBER(SEARCH("rx 9",J2&" "&K2)),AND(IFERROR(N2>=120,FALSE),ISNUMBER(SEARCH("gaming",A2&" "&C2)))),"Gaming",IF(OR(ISNUMBER(SEARCH("thinkpad",C2)),ISNUMBER(SEARCH("latitude",C2)),ISNUMBER(SEARCH("probook",C2)),ISNUMBER(SEARCH("elitebook",C2)),ISNUMBER(SEARCH("office",A2&" "&Q2)),ISNUMBER(SEARCH("business",A2&" "&Q2)),AND(ISNUMBER(SEARCH("windows 11 pro",I2)),J2="Integrated")),"Office / Business",IF(OR(ISNUMBER(SEARCH("creator",A2&" "&Q2)),ISNUMBER(SEARCH("studio",A2&" "&C2)),ISNUMBER(SEARCH("workstation",A2&" "&C2)),ISNUMBER(SEARCH("precision",A2&" "&C2)),ISNUMBER(SEARCH("zbook",A2&" "&C2))),"Creator / Professional","Normal Use")))) -> Gaming | E2: 16 | F2: Core i7 | G2: 16 | H2: 1000 | I2: Windows 11 Home | J2: Dedicated | K2: NVIDIA GeForce RTX 5060 | L2: FHD | M2: FHD+ | N2: 165 | O2: Not Provided | P2: Eclipse Gray | Q2: ROG Nebula Display | Tri-Fan Technology | R2: Wi-Fi 7 | S2: 4.4 | T2: 589 | U2: 438210.9 | V2: 438210.9 | W2: =((V2-U2)/V2)*100 -> 0 | X2: =IF(W2>0,"Yes","No") -> No | Y2: 25993.47 | Z2: 29-09-2026 | AC2: https://www.amazon.com/ASUS-ROG-Strix-Gaming-Laptop/dp/B0DZZWMB2L/ref=sr_1_1?crid=3LC9VL11Q1Y6Z&dib=eyJ2IjoiMSJ9.U2f6tF7U4FXBlufzzxuXjnv_GdNqW7CiSoYDvSuongDXJWA625NT4G_HcCMR46-_8bO8rQDLwftxYPs9ljScRM_SbL8_cN8VvuCkUgnOvSOoHzDcdKKiOcdz1oG0PnxfJTbvu8TzfUsLExe1ajxbM3g_sTV4ZqFymj-480Or8qxXeNsikJI5RdR6NG_pfV_r6WfgdZpalTD-kYdJcPz9f5qE1Z09Dq84ivovAw8Fsr4.ve32C26LJDBbbUmFYHkl1TTlVlSujzPtZELPqGRBN1w&dib_tag=se&keywords=gaming+laptops&qid=1789819786&sprefix=%2Caps%2C392&sr=8-1
A3: Acer Nitro V 16S AI Gaming Laptop | AMD Ryzen 7 260 Processor | NVIDIA GeForce RTX 5060 Laptop GPU (572 AI Tops) | 16" WUXGA IPS 180Hz Display | 32GB DDR5 | 1TB Gen 4 SSD | Wi-Fi 6 | ANV16S-41-R2AJ | B3: Acer | C3: Acer Nitro V 16S AI | D3: =IF(OR(ISNUMBER(SEARCH("charger",A3)),ISNUMBER(SEARCH("cable",A3)),ISNUMBER(SEARCH("adapter",A3)),ISNUMBER(SEARCH("dock",A3)),ISNUMBER(SEARCH("replacement",A3))),"Accessory / Other",IF(OR(J3="Dedicated",ISNUMBER(SEARCH("rtx",J3&" "&K3)),ISNUMBER(SEARCH("gtx",J3&" "&K3)),ISNUMBER(SEARCH("rx 5",J3&" "&K3)),ISNUMBER(SEARCH("rx 6",J3&" "&K3)),ISNUMBER(SEARCH("rx 7",J3&" "&K3)),ISNUMBER(SEARCH("rx 8",J3&" "&K3)),ISNUMBER(SEARCH("rx 9",J3&" "&K3)),AND(IFERROR(N3>=120,FALSE),ISNUMBER(SEARCH("gaming",A3&" "&C3)))),"Gaming",IF(OR(ISNUMBER(SEARCH("thinkpad",C3)),ISNUMBER(SEARCH("latitude",C3)),ISNUMBER(SEARCH("probook",C3)),ISNUMBER(SEARCH("elitebook",C3)),ISNUMBER(SEARCH("office",A3&" "&Q3)),ISNUMBER(SEARCH("business",A3&" "&Q3)),AND(ISNUMBER(SEARCH("windows 11 pro",I3)),J3="Integrated")),"Office / Business",IF(OR(ISNUMBER(SEARCH("creator",A3&" "&Q3)),ISNUMBER(SEARCH("studio",A3&" "&C3)),ISNUMBER(SEARCH("workstation",A3&" "&C3)),ISNUMBER(SEARCH("precision",A3&" "&C3)),ISNUMBER(SEARCH("zbook",A3&" "&C3))),"Creator / Professional","Normal Use")))) -> Gaming | E3: 16 | F3: Ryzen 7 | G3: 32 | H3: 1000 | I3: Windows 11 Home | J3: Dedicated | K3: NVIDIA GeForce RTX 5060 | L3: WUXGA | M3: WUXGA | N3: 180 | O3: Not Provided | P3: Black | Q3: Backlit Keyboard | Numeric Keypad | R3: Wi-Fi 6 | S3: 4.4 | T3: 341 | U3: 401900.98 | V3: 401900.98 | W3: =((V3-U3)/V3)*100 -> 0 | X3: =IF(W3>0,"Yes","No") -> No | Y3: 22853.08 | Z3: 29-09-2026 | AC3: https://www.amazon.com/Gaming-Processor-GeForce-Display-ANV16S-41-R2AJ/dp/B0F195W823/ref=sr_1_2?crid=3LC9VL11Q1Y6Z&dib=eyJ2IjoiMSJ9.U2f6tF7U4FXBlufzzxuXjnv_GdNqW7CiSoYDvSuongDXJWA625NT4G_HcCMR46-_8bO8rQDLwftxYPs9ljScRM_SbL8_cN8VvuCkUgnOvSOoHzDcdKKiOcdz1oG0PnxfJTbvu8TzfUsLExe1ajxbM3g_sTV4ZqFymj-480Or8qxXeNsikJI5RdR6NG_pfV_r6WfgdZpalTD-kYdJcPz9f5qE1Z09Dq84ivovAw8Fsr4.ve32C26LJDBbbUmFYHkl1TTlVlSujzPtZELPqGRBN1w&dib_tag=se&keywords=gaming+laptops&qid=1789819786&sprefix=%2Caps%2C392&sr=8-2
A4: FUNYET Gaming Laptop,Window 11 Pro Laptop Computer, 15.6 Inch Lap Top PC 2026, AMD Ryzen 7 6800H Processor,24GB DDR5 1TB SSD, FHD Display,WiFi 5,BT5.0,Backlit Keyboard,Office 365 for Business,Work | B4: FUNYET | C4: NY-19 | D4: =IF(OR(ISNUMBER(SEARCH("charger",A4)),ISNUMBER(SEARCH("cable",A4)),ISNUMBER(SEARCH("adapter",A4)),ISNUMBER(SEARCH("dock",A4)),ISNUMBER(SEARCH("replacement",A4))),"Accessory / Other",IF(OR(J4="Dedicated",ISNUMBER(SEARCH("rtx",J4&" "&K4)),ISNUMBER(SEARCH("gtx",J4&" "&K4)),ISNUMBER(SEARCH("rx 5",J4&" "&K4)),ISNUMBER(SEARCH("rx 6",J4&" "&K4)),ISNUMBER(SEARCH("rx 7",J4&" "&K4)),ISNUMBER(SEARCH("rx 8",J4&" "&K4)),ISNUMBER(SEARCH("rx 9",J4&" "&K4)),AND(IFERROR(N4>=120,FALSE),ISNUMBER(SEARCH("gaming",A4&" "&C4)))),"Gaming",IF(OR(ISNUMBER(SEARCH("thinkpad",C4)),ISNUMBER(SEARCH("latitude",C4)),ISNUMBER(SEARCH("probook",C4)),ISNUMBER(SEARCH("elitebook",C4)),ISNUMBER(SEARCH("office",A4&" "&Q4)),ISNUMBER(SEARCH("business",A4&" "&Q4)),AND(ISNUMBER(SEARCH("windows 11 pro",I4)),J4="Integrated")),"Office / Business",IF(OR(ISNUMBER(SEARCH("creator",A4&" "&Q4)),ISNUMBER(SEARCH("studio",A4&" "&C4)),ISNUMBER(SEARCH("workstation",A4&" "&C4)),ISNUMBER(SEARCH("precision",A4&" "&C4)),ISNUMBER(SEARCH("zbook",A4&" "&C4))),"Creator / Professional","Normal Use")))) -> Office / Business | E4: 15.6 | F4: AMD Ryzen 7 6800H Processor | G4: 24 | H4: 24 | I4: Not Provided | J4: Not Provided | K4: Not Provided | L4: FHD | M4: FHD | O4: Not Provided | P4: Not Provided | Q4: Backlit Keyboard | Office 365 | DDR5 | R4: WiFi 5 | S4: 4.4 | T4: 11 | U4: 188476.23 | V4: 235595.98 | W4: =((V4-U4)/V4)*100 -> 20.000235 | X4: =IF(W4>0,"Yes","No") -> Yes | Y4: 19036.38 | Z4: 29-09-2026 | AC4: https://aax-us-east-retail-direct.amazon.com/x/c/JMCHTnhL8umEpbEe6Zu91EEAAAGguZKT-wEAAAH2AQBvbm9fdHhuX2JpZDUgICBvbm9fdHhuX2ltcDIgICDSp6fG/clv1c_ek-YxPHTIsbQDZHyXAN0czJZ7dkYWTHQfUUaNL7cqruFGncTbjpkfliEOcR9kvNTvVUBPapguj3PY9ROEQsgaQ_2Ry8nv82qkGiPYM8bkDvZpnENiqsPdq2-_-wnqpLx1wBjP8D4A0tk0Hy4rqF3fzkVlI9GgBTrhhSwzyt6wA6fGm0ZNOBszNEcl-b_N1nGsC8mdMxjtI9ROB-dt0bZ4JLPjd4-T4lX8If2YPGNbyYraQGxO2J9s5esvhU14A7h5_Yl4EdpIcG6Kr3Kycha2SO70PRA5M8_uBHO7EgwyIsEYUIz4Vjhe-5yLYcqCwLN38I1W8fZ-YCFL6BtUSWO6-b4awLn6t6FMLi9Vex3Sje_s6zFVwJBJPoCrh4tH2Q5RHYFtcHmeWivuZp41r2YCAWg-pcN9FEtEM3PpRUrIVDd8NOE5l1Tmn2cZ9vWdPRN6qFGJu2KaPU29D0vHOEqbHHKGDuvL58o1oe8ccNDurFOT29ZGrbIHPdo1mLzjdnjiQms24r7GJZgb593LDS8jNSt5nSbrjtAdMl5XIsTvBUP3XG4mcEsjPL7jcdUhhZp4Z0jvsynB5BhaAxEMQHoiqtYus2MWm93ol3CqcQPg6J21w8PBMwUSzYj54oIY1dEyg2Jr2QPz23VHj9YcgghGGk-rdUju9wKEPofff_Bc-wG43HXrMctUj64DkKPG0F3-gToJFIyC-ZTy6FSDLm9lDDqTmFOn56B8xvtyeBJQ7h7wwzRYku0-3kiQ8NvRAr33x8ttKaGBMYBftRFs6a2reDRWf-Sk6cE84F7px8izROGYVLqzvxvOMi2I2Dr3P8agJ5NwX2SXshVMCrTX_ADQ6u5l5q3xnkgsxoBc8BB39gco86RK9v4-84G7Cqq3-Wez9zv2GgoI8TEiQnPM6R0ZVpI1QCDinln_91YDU5MEdz3U3JL9oLUBiWK8f5XIaiVp_PYA_eZ90Ip0vpYJTQS3E2-N7oXgQsDMMia9Au_-9aJZuTwmXRPP9zXByseC5qqld5iRsg_oQqUyaHw3_NrB4qtkBxKDxXoIRrDnym-k-pWL6_fQ-B12NR7yZLH1sSKRbSKyzNqrOhZyFXPN03lJ54y2__GO34g6KLA4m_4mEHheO6hNn1oVVCoTJQ3v1uyH_OyJbMlNDBborpbux1kVphgh2Ip4W56T7dOX69MBDPuEk6LpXQ9d1DB4RiHbchDusWH8_fSV87B3nNPPnxts9t24GudJ3e59CMsGsdODcCVIYybQTtkyn9MnUleH926evLedghO2sXNQ3KeFkPjf1g7dVm09R07z4a7Z5AywO9oaFQWNAO3QrUp6de4cSdqlhT6WU7lYza1-qjPLSBKg8xSMhSMTkwMdxI0m0n8aSR-SB2bS0c2jn_BC6y_y4IlrfjDiv7EXgyjAnlg1t6550z0tHc9RGKsDCcTqztoCbbV0PYAPmGoEqwcSUU0GgBitHUsCiR_U94KYwcrJvQJDWMmGFPze4OePIhkVku4LJv2OnORQXVSQUWlTWr-UpRElXjE5bu5JH6ZJALZikM5kypAZMMpvhoK6lZwdNcP3Byvpm5Kf_Q0tBNn1J-7_CeGPrNKe4sRHzoOF6PhGNZ_yay4Ais4Qxfzmh7A1rA2nQiRYJh26shOhsNAIMQJ0O36_RemHxmEoqAE0m3M3n8gqEwoyw/https://www.amazon.com/FUNYET-Computer-Processor-Keyboard-Business/dp/B0H4JHNJ4V/ref=sxin_15_sbv_search_btf?content-id=amzn1.sym.a120b15e-b9f5-458c-b2ab-4fe23ec1befc%3Aamzn1.sym.a120b15e-b9f5-458c-b2ab-4fe23ec1befc&crid=3LC9VL11Q1Y6Z&cv_ct_cx=gaming+laptops&keywords=gaming+laptops&pd_rd_i=B0H4JHNJ4V&pd_rd_r=8add4ce2-b5e2-4bbd-b9a8-49698a5c6944&pd_rd_w=z6Ku0&pd_rd_wg=yoAue&pf_rd_p=a120b15e-b9f5-458c-b2ab-4fe23ec1befc&pf_rd_r=VZB2FV2SMZJTYGFZXGGY&qid=1789819786&sbo=9ZOMT9Jm0JH%2Ft%2BWi68iDSA%3D%3D&sprefix=%2Caps%2C392&sr=1-1-b8f34313-536f-475f-9207-a7c427a641c1
A5: KAIGERR Gaming Laptop, Laptop with AMD Ryzen 7430U(Up to 4.3GHz), 16GB DDR4 512GB SSD Laptop Computer, 1920P FHD Display, WiFi 6, USB3.2, Type_C, Webcam Cover Slide | B5: KAIGERR | C5: LX16PRO | D5: =IF(OR(ISNUMBER(SEARCH("charger",A5)),ISNUMBER(SEARCH("cable",A5)),ISNUMBER(SEARCH("adapter",A5)),ISNUMBER(SEARCH("dock",A5)),ISNUMBER(SEARCH("replacement",A5))),"Accessory / Other",IF(OR(J5="Dedicated",ISNUMBER(SEARCH("rtx",J5&" "&K5)),ISNUMBER(SEARCH("gtx",J5&" "&K5)),ISNUMBER(SEARCH("rx 5",J5&" "&K5)),ISNUMBER(SEARCH("rx 6",J5&" "&K5)),ISNUMBER(SEARCH("rx 7",J5&" "&K5)),ISNUMBER(SEARCH("rx 8",J5&" "&K5)),ISNUMBER(SEARCH("rx 9",J5&" "&K5)),AND(IFERROR(N5>=120,FALSE),ISNUMBER(SEARCH("gaming",A5&" "&C5)))),"Gaming",IF(OR(ISNUMBER(SEARCH("thinkpad",C5)),ISNUMBER(SEARCH("latitude",C5)),ISNUMBER(SEARCH("probook",C5)),ISNUMBER(SEARCH("elitebook",C5)),ISNUMBER(SEARCH("office",A5&" "&Q5)),ISNUMBER(SEARCH("business",A5&" "&Q5)),AND(ISNUMBER(SEARCH("windows 11 pro",I5)),J5="Integrated")),"Office / Business",IF(OR(ISNUMBER(SEARCH("creator",A5&" "&Q5)),ISNUMBER(SEARCH("studio",A5&" "&C5)),ISNUMBER(SEARCH("workstation",A5&" "&C5)),ISNUMBER(SEARCH("precision",A5&" "&C5)),ISNUMBER(SEARCH("zbook",A5&" "&C5))),"Creator / Professional","Normal Use")))) -> Normal Use | E5: 16 | F5: AMD R Series | G5: 16 | H5: 512 | I5: Windows 11 | J5: Integrated | K5: Not Provided | L5: FHD | M5: FHD | O5: Up to 4.3GHz | P5: Sophisticated Grey | Q5: Lightweight | Numeric Keypad | Webcam Cover | R5: WiFi 6 | USB3.2 | S5: 4.7 | T5: 18 | U5: 155215.23 | V5: 471194.73 | W5: =((V5-U5)/V5)*100 -> 67.059218 | X5: =IF(W5>0,"Yes","No") -> Yes | Y5: 18759.2 | Z5: 29-09-2026 | AB5: https://m.media-amazon.com/images/I/71kEunh4iBL._AC_UY218_.jpg | AC5: https://www.amazon.com/KAIGERR-Gaming-Laptop-Computer-Display/dp/B0HFSB44KN/ref=sr_1_4?crid=3LC9VL11Q1Y6Z&dib=eyJ2IjoiMSJ9.U2f6tF7U4FXBlufzzxuXjnv_GdNqW7CiSoYDvSuongDXJWA625NT4G_HcCMR46-_8bO8rQDLwftxYPs9ljScRM_SbL8_cN8VvuCkUgnOvSOoHzDcdKKiOcdz1oG0PnxfJTbvu8TzfUsLExe1ajxbM3g_sTV4ZqFymj-480Or8qxXeNsikJI5RdR6NG_pfV_r6WfgdZpalTD-kYdJcPz9f5qE1Z09Dq84ivovAw8Fsr4.ve32C26LJDBbbUmFYHkl1TTlVlSujzPtZELPqGRBN1w&dib_tag=se&keywords=gaming+laptops&qid=1789819786&sprefix=%2Caps%2C392&sr=8-4
A6: 18.5 Inch Gaming Laptop with 7000 mAh Battery,AMD Ryzen 7430U UP to 4.3GHZ | B6: MALLRACE | C6: AX18-7430U | D6: =IF(OR(ISNUMBER(SEARCH("charger",A6)),ISNUMBER(SEARCH("cable",A6)),ISNUMBER(SEARCH("adapter",A6)),ISNUMBER(SEARCH("dock",A6)),ISNUMBER(SEARCH("replacement",A6))),"Accessory / Other",IF(OR(J6="Dedicated",ISNUMBER(SEARCH("rtx",J6&" "&K6)),ISNUMBER(SEARCH("gtx",J6&" "&K6)),ISNUMBER(SEARCH("rx 5",J6&" "&K6)),ISNUMBER(SEARCH("rx 6",J6&" "&K6)),ISNUMBER(SEARCH("rx 7",J6&" "&K6)),ISNUMBER(SEARCH("rx 8",J6&" "&K6)),ISNUMBER(SEARCH("rx 9",J6&" "&K6)),AND(IFERROR(N6>=120,FALSE),ISNUMBER(SEARCH("gaming",A6&" "&C6)))),"Gaming",IF(OR(ISNUMBER(SEARCH("thinkpad",C6)),ISNUMBER(SEARCH("latitude",C6)),ISNUMBER(SEARCH("probook",C6)),ISNUMBER(SEARCH("elitebook",C6)),ISNUMBER(SEARCH("office",A6&" "&Q6)),ISNUMBER(SEARCH("business",A6&" "&Q6)),AND(ISNUMBER(SEARCH("windows 11 pro",I6)),J6="Integrated")),"Office / Business",IF(OR(ISNUMBER(SEARCH("creator",A6&" "&Q6)),ISNUMBER(SEARCH("studio",A6&" "&C6)),ISNUMBER(SEARCH("workstation",A6&" "&C6)),ISNUMBER(SEARCH("precision",A6&" "&C6)),ISNUMBER(SEARCH("zbook",A6&" "&C6))),"Creator / Professional","Normal Use")))) -> Normal Use | E6: 18.5 | F6: Ryzen 5 | G6: 16 | H6: 512 | I6: Windows 11 | J6: Integrated | K6: Not Provided | L6: Not Provided | M6: Not Provided | O6: UP to 4.3GHZ | P6: Matte Grey | Q6: 18.5 inch laptop | 7000mAh Large Battery | AMD Ryzen 7430U | HD Audio | Card Slot | 7000 mAh | R6: Not Provided | S6: 4.8 | T6: 18 | U6: 182655.55 | V6: 443477.23 | W6: =((V6-U6)/V6)*100 -> 58.812868 | X6: =IF(W6>0,"Yes","No") -> Yes | Y6: 21996.61 | Z6: 29-09-2026 | AB6: https://m.media-amazon.com/images/I/715V4VP-nfL._AC_UY218_.jpg | AC6: https://www.amazon.com/Gaming-Laptop-Battery-Ryzen-4-3GHZ/dp/B0HF3J55CY/ref=sr_1_6?crid=3LC9VL11Q1Y6Z&dib=eyJ2IjoiMSJ9.U2f6tF7U4FXBlufzzxuXjnv_GdNqW7CiSoYDvSuongDXJWA625NT4G_HcCMR46-_8bO8rQDLwftxYPs9ljScRM_SbL8_cN8VvuCkUgnOvSOoHzDcdKKiOcdz1oG0PnxfJTbvu8TzfUsLExe1ajxbM3g_sTV4ZqFymj-480Or8qxXeNsikJI5RdR6NG_pfV_r6WfgdZpalTD-kYdJcPz9f5qE1Z09Dq84ivovAw8Fsr4.ve32C26LJDBbbUmFYHkl1TTlVlSujzPtZELPqGRBN1w&dib_tag=se&keywords=gaming+laptops&qid=1789819786&sprefix=%2Caps%2C392&sr=8-6
A7: KAIGERR Gaming Laptop, 24GB DDR5 512GB NVMe SSD Laptop Computer with AMD Ryzen 7 H255(8C/16T, Up to 4.9GHz), 16.0 inch Windows 11 Laptop, Radeon RX Vega 8 Graphics,WiFi 6, Backlit KB | B7: KAIGERR | C7: S16 | D7: =IF(OR(ISNUMBER(SEARCH("charger",A7)),ISNUMBER(SEARCH("cable",A7)),ISNUMBER(SEARCH("adapter",A7)),ISNUMBER(SEARCH("dock",A7)),ISNUMBER(SEARCH("replacement",A7))),"Accessory / Other",IF(OR(J7="Dedicated",ISNUMBER(SEARCH("rtx",J7&" "&K7)),ISNUMBER(SEARCH("gtx",J7&" "&K7)),ISNUMBER(SEARCH("rx 5",J7&" "&K7)),ISNUMBER(SEARCH("rx 6",J7&" "&K7)),ISNUMBER(SEARCH("rx 7",J7&" "&K7)),ISNUMBER(SEARCH("rx 8",J7&" "&K7)),ISNUMBER(SEARCH("rx 9",J7&" "&K7)),AND(IFERROR(N7>=120,FALSE),ISNUMBER(SEARCH("gaming",A7&" "&C7)))),"Gaming",IF(OR(ISNUMBER(SEARCH("thinkpad",C7)),ISNUMBER(SEARCH("latitude",C7)),ISNUMBER(SEARCH("probook",C7)),ISNUMBER(SEARCH("elitebook",C7)),ISNUMBER(SEARCH("office",A7&" "&Q7)),ISNUMBER(SEARCH("business",A7&" "&Q7)),AND(ISNUMBER(SEARCH("windows 11 pro",I7)),J7="Integrated")),"Office / Business",IF(OR(ISNUMBER(SEARCH("creator",A7&" "&Q7)),ISNUMBER(SEARCH("studio",A7&" "&C7)),ISNUMBER(SEARCH("workstation",A7&" "&C7)),ISNUMBER(SEARCH("precision",A7&" "&C7)),ISNUMBER(SEARCH("zbook",A7&" "&C7))),"Creator / Professional","Normal Use")))) -> Normal Use | E7: 16 | F7: AMD Ryzen 7 | G7: 24 | H7: 512 | I7: Windows 11 | J7: Integrated | K7: Radeon RX Vega 8 Graphics | L7: Not Provided | M7: Not Provided | O7: Up to 4.9GHz | P7: Newest Grey | Q7: Backlit Keyboard | High Performance | Lightweight | Numeric Keypad | R7: WiFi 6 | S7: 3.9 | T7: 26 | U7: 526629.73 | V7: 526629.73 | W7: =((V7-U7)/V7)*100 -> 0 | X7: =IF(W7>0,"Yes","No") -> No | Y7: 19244.26 | Z7: 29-09-2026 | AB7: https://m.media-amazon.com/images/I/81m-bBjxVcL._AC_UY218_.jpg | AC7: https://www.amazon.com/KAIGERR-Computer-Windows-Graphics-Backlit/dp/B0HF7XD4VY/ref=sr_1_7?crid=3LC9VL11Q1Y6Z&dib=eyJ2IjoiMSJ9.U2f6tF7U4FXBlufzzxuXjnv_GdNqW7CiSoYDvSuongDXJWA625NT4G_HcCMR46-_8bO8rQDLwftxYPs9ljScRM_SbL8_cN8VvuCkUgnOvSOoHzDcdKKiOcdz1oG0PnxfJTbvu8TzfUsLExe1ajxbM3g_sTV4ZqFymj-480Or8qxXeNsikJI5RdR6NG_pfV_r6WfgdZpalTD-kYdJcPz9f5qE1Z09Dq84ivovAw8Fsr4.ve32C26LJDBbbUmFYHkl1TTlVlSujzPtZELPqGRBN1w&dib_tag=se&keywords=gaming+laptops&qid=1789819786&sprefix=%2Caps%2C392&sr=8-7
A8: ASUS ROG Strix G16 (2025) Gaming Laptop, 16" ROG Nebula 16:10 2.5K 240Hz/3ms, NVIDIA® GeForce RTX™ 5070 Ti, Intel® Core™ Ultra 9 Processor 275HX, 32GB DDR5, 1TB SSD, Wi-Fi 7, Win11 Home, G615LR-AS96 | B8: ASUS | C8: ROG Strix G16 | D8: =IF(OR(ISNUMBER(SEARCH("charger",A8)),ISNUMBER(SEARCH("cable",A8)),ISNUMBER(SEARCH("adapter",A8)),ISNUMBER(SEARCH("dock",A8)),ISNUMBER(SEARCH("replacement",A8))),"Accessory / Other",IF(OR(J8="Dedicated",ISNUMBER(SEARCH("rtx",J8&" "&K8)),ISNUMBER(SEARCH("gtx",J8&" "&K8)),ISNUMBER(SEARCH("rx 5",J8&" "&K8)),ISNUMBER(SEARCH("rx 6",J8&" "&K8)),ISNUMBER(SEARCH("rx 7",J8&" "&K8)),ISNUMBER(SEARCH("rx 8",J8&" "&K8)),ISNUMBER(SEARCH("rx 9",J8&" "&K8)),AND(IFERROR(N8>=120,FALSE),ISNUMBER(SEARCH("gaming",A8&" "&C8)))),"Gaming",IF(OR(ISNUMBER(SEARCH("thinkpad",C8)),ISNUMBER(SEARCH("latitude",C8)),ISNUMBER(SEARCH("probook",C8)),ISNUMBER(SEARCH("elitebook",C8)),ISNUMBER(SEARCH("office",A8&" "&Q8)),ISNUMBER(SEARCH("business",A8&" "&Q8)),AND(ISNUMBER(SEARCH("windows 11 pro",I8)),J8="Integrated")),"Office / Business",IF(OR(ISNUMBER(SEARCH("creator",A8&" "&Q8)),ISNUMBER(SEARCH("studio",A8&" "&C8)),ISNUMBER(SEARCH("workstation",A8&" "&C8)),ISNUMBER(SEARCH("precision",A8&" "&C8)),ISNUMBER(SEARCH("zbook",A8&" "&C8))),"Creator / Professional","Normal Use")))) -> Gaming | E8: 16 | F8: Intel Core Ultra 9 | G8: 32 | H8: 1000 | I8: Windows 11 Home | J8: Dedicated | K8: NVIDIA GeForce RTX 5070 Ti | L8: 2.5K | M8: Not Provided | N8: 240 | O8: Not Provided | P8: Black | Q8: Backlit Keyboard | R8: Wi-Fi 7 | S8: 4.3 | T8: 225 | U8: 706513.53 | V8: 706513.53 | W8: =((V8-U8)/V8)*100 -> 0 | X8: =IF(W8>0,"Yes","No") -> No | Y8: 25882.6 | Z8: 29-09-2026 | AB8: https://m.media-amazon.com/images/I/71WH7jtyWpL._AC_UY218_.jpg | AC8: https://www.amazon.com/ASUS-Gaming-Laptop-Nebula-Display/dp/B0DW1X5YCQ/ref=sr_1_9?crid=3LC9VL11Q1Y6Z&dib=eyJ2IjoiMSJ9.U2f6tF7U4FXBlufzzxuXjnv_GdNqW7CiSoYDvSuongDXJWA625NT4G_HcCMR46-_8bO8rQDLwftxYPs9ljScRM_SbL8_cN8VvuCkUgnOvSOoHzDcdKKiOcdz1oG0PnxfJTbvu8TzfUsLExe1ajxbM3g_sTV4ZqFymj-480Or8qxXeNsikJI5RdR6NG_pfV_r6WfgdZpalTD-kYdJcPz9f5qE1Z09Dq84ivovAw8Fsr4.ve32C26LJDBbbUmFYHkl1TTlVlSujzPtZELPqGRBN1w&dib_tag=se&keywords=gaming+laptops&qid=1789819786&sprefix=%2Caps%2C392&sr=8-9
A9: Razer Blade 16 (2026) Gaming Laptop, RTX 5070 Ti, 32GB DDR5, 1TB, Black | B9: Razer | C9: Blade 16 | D9: =IF(OR(ISNUMBER(SEARCH("charger",A9)),ISNUMBER(SEARCH("cable",A9)),ISNUMBER(SEARCH("adapter",A9)),ISNUMBER(SEARCH("dock",A9)),ISNUMBER(SEARCH("replacement",A9))),"Accessory / Other",IF(OR(J9="Dedicated",ISNUMBER(SEARCH("rtx",J9&" "&K9)),ISNUMBER(SEARCH("gtx",J9&" "&K9)),ISNUMBER(SEARCH("rx 5",J9&" "&K9)),ISNUMBER(SEARCH("rx 6",J9&" "&K9)),ISNUMBER(SEARCH("rx 7",J9&" "&K9)),ISNUMBER(SEARCH("rx 8",J9&" "&K9)),ISNUMBER(SEARCH("rx 9",J9&" "&K9)),AND(IFERROR(N9>=120,FALSE),ISNUMBER(SEARCH("gaming",A9&" "&C9)))),"Gaming",IF(OR(ISNUMBER(SEARCH("thinkpad",C9)),ISNUMBER(SEARCH("latitude",C9)),ISNUMBER(SEARCH("probook",C9)),ISNUMBER(SEARCH("elitebook",C9)),ISNUMBER(SEARCH("office",A9&" "&Q9)),ISNUMBER(SEARCH("business",A9&" "&Q9)),AND(ISNUMBER(SEARCH("windows 11 pro",I9)),J9="Integrated")),"Office / Business",IF(OR(ISNUMBER(SEARCH("creator",A9&" "&Q9)),ISNUMBER(SEARCH("studio",A9&" "&C9)),ISNUMBER(SEARCH("workstation",A9&" "&C9)),ISNUMBER(SEARCH("precision",A9&" "&C9)),ISNUMBER(SEARCH("zbook",A9&" "&C9))),"Creator / Professional","Normal Use")))) -> Gaming | E9: 16 | F9: Core i9 | G9: 32 | H9: 1000 | I9: Windows 11 Home | J9: RTX 5070 Ti | K9: RTX 5070 Ti | L9: Not Provided | M9: Not Provided | O9: Not Provided | P9: Black | Q9: Intel NPU | Vapor Chamber Cooling | Windows Hello | Wi-Fi 7 | 90 WHr | CNC Milled Aluminum | THX Spatial Audio | Pluton Security Processor | Kensington Security Slot | TPM 2.0 | Anodized Black Finish | Thunderbolt 5 and Thunderbolt 4 Ready | R9: Not Provided | S9: 5 | T9: 2 | U9: 970109.73 | V9: 970109.73 | W9: =((V9-U9)/V9)*100 -> 0 | X9: =IF(W9>0,"Yes","No") -> No | Y9: 24225.1 | Z9: 28-09-2026 | AB9: https://m.media-amazon.com/images/I/719SQ1o+TSL._AC_UY218_.jpg | AC9: https://www.amazon.com/Razer-Blade-Gaming-Laptop-Black/dp/B0H31TTZJT/ref=sr_1_10?crid=3LC9VL11Q1Y6Z&dib=eyJ2IjoiMSJ9.U2f6tF7U4FXBlufzzxuXjnv_GdNqW7CiSoYDvSuongDXJWA625NT4G_HcCMR46-_8bO8rQDLwftxYPs9ljScRM_SbL8_cN8VvuCkUgnOvSOoHzDcdKKiOcdz1oG0PnxfJTbvu8TzfUsLExe1ajxbM3g_sTV4ZqFymj-480Or8qxXeNsikJI5RdR6NG_pfV_r6WfgdZpalTD-kYdJcPz9f5qE1Z09Dq84ivovAw8Fsr4.ve32C26LJDBbbUmFYHkl1TTlVlSujzPtZELPqGRBN1w&dib_tag=se&keywords=gaming+laptops&qid=1789819786&sprefix=%2Caps%2C392&sr=8-10
A10: ASUS ROG Strix G16 Gaming Laptop, 16" 16:10 FHD+ 165Hz/3ms, NVIDIA GeForce RTX 5050 Laptop GPU, Intel Core i5 Processor 14450HX, 16GB DDR5-5600, 512GB PCIe Gen 4 SSD, Wi-Fi 7, Win11 Home, G615JHR-DS53 | B10: ASUS | C10: G615JHR-DS53 | D10: =IF(OR(ISNUMBER(SEARCH("charger",A10)),ISNUMBER(SEARCH("cable",A10)),ISNUMBER(SEARCH("adapter",A10)),ISNUMBER(SEARCH("dock",A10)),ISNUMBER(SEARCH("replacement",A10))),"Accessory / Other",IF(OR(J10="Dedicated",ISNUMBER(SEARCH("rtx",J10&" "&K10)),ISNUMBER(SEARCH("gtx",J10&" "&K10)),ISNUMBER(SEARCH("rx 5",J10&" "&K10)),ISNUMBER(SEARCH("rx 6",J10&" "&K10)),ISNUMBER(SEARCH("rx 7",J10&" "&K10)),ISNUMBER(SEARCH("rx 8",J10&" "&K10)),ISNUMBER(SEARCH("rx 9",J10&" "&K10)),AND(IFERROR(N10>=120,FALSE),ISNUMBER(SEARCH("gaming",A10&" "&C10)))),"Gaming",IF(OR(ISNUMBER(SEARCH("thinkpad",C10)),ISNUMBER(SEARCH("latitude",C10)),ISNUMBER(SEARCH("probook",C10)),ISNUMBER(SEARCH("elitebook",C10)),ISNUMBER(SEARCH("office",A10&" "&Q10)),ISNUMBER(SEARCH("business",A10&" "&Q10)),AND(ISNUMBER(SEARCH("windows 11 pro",I10)),J10="Integrated")),"Office / Business",IF(OR(ISNUMBER(SEARCH("creator",A10&" "&Q10)),ISNUMBER(SEARCH("studio",A10&" "&C10)),ISNUMBER(SEARCH("workstation",A10&" "&C10)),ISNUMBER(SEARCH("precision",A10&" "&C10)),ISNUMBER(SEARCH("zbook",A10&" "&C10))),"Creator / Professional","Normal Use")))) -> Gaming | E10: 16 | F10: Core i5 | G10: 16 | H10: 512 | I10: Windows 11 Home | J10: Dedicated | K10: NVIDIA GeForce RTX 5050 | L10: FHD | M10: FHD+ | N10: 165 | O10: Not Provided | P10: Eclipse Gray | Q10: Anti Glare Coating | Backlit Keyboard | Wifi | R10: Wi-Fi 7 | U10: 360324.73 | V10: 360324.73 | W10: =((V10-U10)/V10)*100 -> 0 | X10: =IF(W10>0,"Yes","No") -> No | Y10: 27434.78 | Z10: 29-09-2026 | AB10: https://m.media-amazon.com/images/I/81MIF+hN13L._AC_UY218_.jpg | AC10: https://www.amazon.com/ASUS-ROG-Strix-Gaming-Laptop/dp/B0H42CV8H7/ref=sr_1_11?crid=3LC9VL11Q1Y6Z&dib=eyJ2IjoiMSJ9.U2f6tF7U4FXBlufzzxuXjnv_GdNqW7CiSoYDvSuongDXJWA625NT4G_HcCMR46-_8bO8rQDLwftxYPs9ljScRM_SbL8_cN8VvuCkUgnOvSOoHzDcdKKiOcdz1oG0PnxfJTbvu8TzfUsLExe1ajxbM3g_sTV4ZqFymj-480Or8qxXeNsikJI5RdR6NG_pfV_r6WfgdZpalTD-kYdJcPz9f5qE1Z09Dq84ivovAw8Fsr4.ve32C26LJDBbbUmFYHkl1TTlVlSujzPtZELPqGRBN1w&dib_tag=se&keywords=gaming+laptops&qid=1789819786&sprefix=%2Caps%2C392&sr=8-11
A11: MALLRACE Gaming Laptop,16GB 512GB SSD Laptop Computer with Numeric KB,AMD Ryzen 5 7430U (Beat Intel i7-1255,up to 4.3GHz), Radeon Graphics,15.6inch FHD Display AMD Laptop,Type_C,WiFi 6 | B11: MALLRACE | C11: LX15PRO | D11: =IF(OR(ISNUMBER(SEARCH("charger",A11)),ISNUMBER(SEARCH("cable",A11)),ISNUMBER(SEARCH("adapter",A11)),ISNUMBER(SEARCH("dock",A11)),ISNUMBER(SEARCH("replacement",A11))),"Accessory / Other",IF(OR(J11="Dedicated",ISNUMBER(SEARCH("rtx",J11&" "&K11)),ISNUMBER(SEARCH("gtx",J11&" "&K11)),ISNUMBER(SEARCH("rx 5",J11&" "&K11)),ISNUMBER(SEARCH("rx 6",J11&" "&K11)),ISNUMBER(SEARCH("rx 7",J11&" "&K11)),ISNUMBER(SEARCH("rx 8",J11&" "&K11)),ISNUMBER(SEARCH("rx 9",J11&" "&K11)),AND(IFERROR(N11>=120,FALSE),ISNUMBER(SEARCH("gaming",A11&" "&C11)))),"Gaming",IF(OR(ISNUMBER(SEARCH("thinkpad",C11)),ISNUMBER(SEARCH("latitude",C11)),ISNUMBER(SEARCH("probook",C11)),ISNUMBER(SEARCH("elitebook",C11)),ISNUMBER(SEARCH("office",A11&" "&Q11)),ISNUMBER(SEARCH("business",A11&" "&Q11)),AND(ISNUMBER(SEARCH("windows 11 pro",I11)),J11="Integrated")),"Office / Business",IF(OR(ISNUMBER(SEARCH("creator",A11&" "&Q11)),ISNUMBER(SEARCH("studio",A11&" "&C11)),ISNUMBER(SEARCH("workstation",A11&" "&C11)),ISNUMBER(SEARCH("precision",A11&" "&C11)),ISNUMBER(SEARCH("zbook",A11&" "&C11))),"Creator / Professional","Normal Use")))) -> Normal Use | E11: 15.6 | F11: Ryzen 5 | G11: 16 | H11: 512 | I11: Windows 11 Pro | J11: AMD Radeon™ Graphics | K11: Radeon Graphics | L11: FHD | M11: FHD | O11: up to 4.3GHz | P11: Matte Grey | Q11: Lightweight | Numeric Keypad | R11: WiFi 6 | S11: 4.5 | T11: 20 | U11: 138584.73 | V11: 235595.98 | W11: =((V11-U11)/V11)*100 -> 41.176955 | X11: =IF(W11>0,"Yes","No") -> Yes | Y11: 18415.51 | Z11: 29-09-2026 | AB11: https://m.media-amazon.com/images/I/71+KUy76p5L._AC_UY218_.jpg | AC11: https://www.amazon.com/MALLRACE-Computer-Numeric-Graphics-15-6inch/dp/B0HFQSZZ26/ref=sr_1_12?crid=3LC9VL11Q1Y6Z&dib=eyJ2IjoiMSJ9.U2f6tF7U4FXBlufzzxuXjnv_GdNqW7CiSoYDvSuongDXJWA625NT4G_HcCMR46-_8bO8rQDLwftxYPs9ljScRM_SbL8_cN8VvuCkUgnOvSOoHzDcdKKiOcdz1oG0PnxfJTbvu8TzfUsLExe1ajxbM3g_sTV4ZqFymj-480Or8qxXeNsikJI5RdR6NG_pfV_r6WfgdZpalTD-kYdJcPz9f5qE1Z09Dq84ivovAw8Fsr4.ve32C26LJDBbbUmFYHkl1TTlVlSujzPtZELPqGRBN1w&dib_tag=se&keywords=gaming+laptops&qid=1789819786&sprefix=%2Caps%2C392&sr=8-12
A12: KAIGERR Gaming Laptop with AMD Ryzen 7430U(Up to 4.3GHz), 16GB DDR4 512GB SSD Laptop Computer, 1920P FHD Display, WiFi 6, USB3.2, Type_C, Webcam Cover Slide | B12: KAIGERR | C12: LX16PRO | D12: =IF(OR(ISNUMBER(SEARCH("charger",A12)),ISNUMBER(SEARCH("cable",A12)),ISNUMBER(SEARCH("adapter",A12)),ISNUMBER(SEARCH("dock",A12)),ISNUMBER(SEARCH("replacement",A12))),"Accessory / Other",IF(OR(J12="Dedicated",ISNUMBER(SEARCH("rtx",J12&" "&K12)),ISNUMBER(SEARCH("gtx",J12&" "&K12)),ISNUMBER(SEARCH("rx 5",J12&" "&K12)),ISNUMBER(SEARCH("rx 6",J12&" "&K12)),ISNUMBER(SEARCH("rx 7",J12&" "&K12)),ISNUMBER(SEARCH("rx 8",J12&" "&K12)),ISNUMBER(SEARCH("rx 9",J12&" "&K12)),AND(IFERROR(N12>=120,FALSE),ISNUMBER(SEARCH("gaming",A12&" "&C12)))),"Gaming",IF(OR(ISNUMBER(SEARCH("thinkpad",C12)),ISNUMBER(SEARCH("latitude",C12)),ISNUMBER(SEARCH("probook",C12)),ISNUMBER(SEARCH("elitebook",C12)),ISNUMBER(SEARCH("office",A12&" "&Q12)),ISNUMBER(SEARCH("business",A12&" "&Q12)),AND(ISNUMBER(SEARCH("windows 11 pro",I12)),J12="Integrated")),"Office / Business",IF(OR(ISNUMBER(SEARCH("creator",A12&" "&Q12)),ISNUMBER(SEARCH("studio",A12&" "&C12)),ISNUMBER(SEARCH("workstation",A12&" "&C12)),ISNUMBER(SEARCH("precision",A12&" "&C12)),ISNUMBER(SEARCH("zbook",A12&" "&C12))),"Creator / Professional","Normal Use")))) -> Normal Use | E12: 16 | F12: AMD R Series | G12: 16 | H12: 512 | I12: Windows 11 | J12: Integrated | K12: Not Provided | L12: FHD | M12: FHD | O12: Up to 4.3GHz | P12: Sophisticated Grey | Q12: Lightweight | Numeric Keypad | Webcam Cover | R12: WiFi 6 | USB3.2 | S12: 5 | T12: 13 | U12: 260541.73 | V12: 260541.73 | W12: =((V12-U12)/V12)*100 -> 0 | X12: =IF(W12>0,"Yes","No") -> No | Y12: 18759.2 | Z12: 29-09-2026 | AB12: https://m.media-amazon.com/images/I/71yhKclypqL._AC_UY218_.jpg | AC12: https://www.amazon.com/KAIGERR-Gaming-Laptop-Computer-Display/dp/B0H93H8V7J/ref=sr_1_13?crid=3LC9VL11Q1Y6Z&dib=eyJ2IjoiMSJ9.U2f6tF7U4FXBlufzzxuXjnv_GdNqW7CiSoYDvSuongDXJWA625NT4G_HcCMR46-_8bO8rQDLwftxYPs9ljScRM_SbL8_cN8VvuCkUgnOvSOoHzDcdKKiOcdz1oG0PnxfJTbvu8TzfUsLExe1ajxbM3g_sTV4ZqFymj-480Or8qxXeNsikJI5RdR6NG_pfV_r6WfgdZpalTD-kYdJcPz9f5qE1Z09Dq84ivovAw8Fsr4.ve32C26LJDBbbUmFYHkl1TTlVlSujzPtZELPqGRBN1w&dib_tag=se&keywords=gaming+laptops&qid=1789819786&sprefix=%2Caps%2C392&sr=8-13
A13: Acer Nitro V Gaming Laptop | Intel Core 5 Processor 210H | NVIDIA GeForce RTX 5050 Laptop GPU | 16" WUXGA IPS 165Hz Display | 8GB DDR5 | 512GB Gen 4 SSD | Wi-Fi 6 | Backlit Keyboard | ANV16-I31-54PT | B13: Acer | C13: Nitro V | D13: =IF(OR(ISNUMBER(SEARCH("charger",A13)),ISNUMBER(SEARCH("cable",A13)),ISNUMBER(SEARCH("adapter",A13)),ISNUMBER(SEARCH("dock",A13)),ISNUMBER(SEARCH("replacement",A13))),"Accessory / Other",IF(OR(J13="Dedicated",ISNUMBER(SEARCH("rtx",J13&" "&K13)),ISNUMBER(SEARCH("gtx",J13&" "&K13)),ISNUMBER(SEARCH("rx 5",J13&" "&K13)),ISNUMBER(SEARCH("rx 6",J13&" "&K13)),ISNUMBER(SEARCH("rx 7",J13&" "&K13)),ISNUMBER(SEARCH("rx 8",J13&" "&K13)),ISNUMBER(SEARCH("rx 9",J13&" "&K13)),AND(IFERROR(N13>=120,FALSE),ISNUMBER(SEARCH("gaming",A13&" "&C13)))),"Gaming",IF(OR(ISNUMBER(SEARCH("thinkpad",C13)),ISNUMBER(SEARCH("latitude",C13)),ISNUMBER(SEARCH("probook",C13)),ISNUMBER(SEARCH("elitebook",C13)),ISNUMBER(SEARCH("office",A13&" "&Q13)),ISNUMBER(SEARCH("business",A13&" "&Q13)),AND(ISNUMBER(SEARCH("windows 11 pro",I13)),J13="Integrated")),"Office / Business",IF(OR(ISNUMBER(SEARCH("creator",A13&" "&Q13)),ISNUMBER(SEARCH("studio",A13&" "&C13)),ISNUMBER(SEARCH("workstation",A13&" "&C13)),ISNUMBER(SEARCH("precision",A13&" "&C13)),ISNUMBER(SEARCH("zbook",A13&" "&C13))),"Creator / Professional","Normal Use")))) -> Gaming | F13: Intel Core 5 Processor 210H | G13: 8 | H13: 8 | I13: Not Provided | J13: NVIDIA GeForce RTX 5050 | K13: NVIDIA GeForce RTX 5050 | L13: WUXGA | M13: WUXGA | N13: 165 | O13: Not Provided | P13: Not Provided | Q13: Backlit Keyboard | IPS | DDR5 | R13: Wi-Fi 6 | S13: 3.7 | T13: 4 | U13: 374183.48 | V13: 374183.48 | W13: =((V13-U13)/V13)*100 -> 0 | X13: =IF(W13>0,"Yes","No") -> No | Y13: 20488.78 | Z13: 29-09-2026 | AB13: https://m.media-amazon.com/images/I/71iSm+PbylL._AC_UY218_.jpg | AC13: https://www.amazon.com/sspa/click?ie=UTF8&spc=MToxMDM2NjU2NzcwMzIwNDU2OjE3ODk4MTk4ODc6c3BfYXRmX25leHQ6MzAxMzUxMjExOTI2ODAyOjowOjo&url=%2FAcer-Processor-GeForce-Keyboard-ANV16-I31-54PT%2Fdp%2FB0CJCNL315%2Fref%3Dsr_1_17_sspa%3Fcrid%3D3LC9VL11Q1Y6Z%26dib%3DeyJ2IjoiMSJ9.ugoRDgk6CPUHAO-vuB2wI78pO390UDdb6RIU-aabDt5oU4otZYiGUnN6i_3bTOJjtcS38F6V6MAp5orniGxaedyNOGAYlDK7d99c9ucqP2kacaNCFHiHGfY9UEeOjwzul9iF8cSC9UucU8Gs5GLNy7FQ0V8OzIpdhNU--RElP62tW8GL2hHkxWv1CovRPUE2ikPC0MLd9pFvg58mnuxLOGLRhpXKRp64sVad5ICo7pE.-xmc_AxVrBglQX_RvSgqSLCabFYrz8FXomxgbbeGO4o%26dib_tag%3Dse%26keywords%3Dgaming%2Blaptops%26qid%3D1789819887%26sprefix%3D%252Caps%252C392%26sr%3D8-17-spons%26xpid%3DMMcXVFo9VX50C%26sp_csd%3Dd2lkZ2V0TmFtZT1zcF9hdGZfbmV4dA%26psc%3D1
A14: Light Gaming Laptop, AMD Ryzen 7430U (Up to 4.3GHz), 16GB 512GB SSD | B14: KAIGERR | C14: LX15PRO | D14: =IF(OR(ISNUMBER(SEARCH("charger",A14)),ISNUMBER(SEARCH("cable",A14)),ISNUMBER(SEARCH("adapter",A14)),ISNUMBER(SEARCH("dock",A14)),ISNUMBER(SEARCH("replacement",A14))),"Accessory / Other",IF(OR(J14="Dedicated",ISNUMBER(SEARCH("rtx",J14&" "&K14)),ISNUMBER(SEARCH("gtx",J14&" "&K14)),ISNUMBER(SEARCH("rx 5",J14&" "&K14)),ISNUMBER(SEARCH("rx 6",J14&" "&K14)),ISNUMBER(SEARCH("rx 7",J14&" "&K14)),ISNUMBER(SEARCH("rx 8",J14&" "&K14)),ISNUMBER(SEARCH("rx 9",J14&" "&K14)),AND(IFERROR(N14>=120,FALSE),ISNUMBER(SEARCH("gaming",A14&" "&C14)))),"Gaming",IF(OR(ISNUMBER(SEARCH("thinkpad",C14)),ISNUMBER(SEARCH("latitude",C14)),ISNUMBER(SEARCH("probook",C14)),ISNUMBER(SEARCH("elitebook",C14)),ISNUMBER(SEARCH("office",A14&" "&Q14)),ISNUMBER(SEARCH("business",A14&" "&Q14)),AND(ISNUMBER(SEARCH("windows 11 pro",I14)),J14="Integrated")),"Office / Business",IF(OR(ISNUMBER(SEARCH("creator",A14&" "&Q14)),ISNUMBER(SEARCH("studio",A14&" "&C14)),ISNUMBER(SEARCH("workstation",A14&" "&C14)),ISNUMBER(SEARCH("precision",A14&" "&C14)),ISNUMBER(SEARCH("zbook",A14&" "&C14))),"Creator / Professional","Normal Use")))) -> Office / Business | E14: 15.6 | F14: Ryzen 5 | G14: 16 | H14: 512 | I14: Windows 11 Pro | J14: Integrated | K14: Not Provided | L14: Not Provided | M14: Not Provided | O14: Up to 4.3GHz | P14: Nice Medium Gray | Q14: laptop | laptop computer | light gaming laptop | R14: Not Provided | S14: 4.6 | T14: 16 | U14: 163524.93 | V14: 268856.98 | W14: =((V14-U14)/V14)*100 -> 39.177726 | X14: =IF(W14>0,"Yes","No") -> Yes | Y14: 18554.09 | Z14: 29-09-2026 | AB14: https://m.media-amazon.com/images/I/71D4xomw-wL._AC_UY218_.jpg | AC14: https://www.amazon.com/Light-Gaming-Laptop-Ryzen-4-3GHz/dp/B0H6B6NH9Y/ref=sr_1_21?crid=3LC9VL11Q1Y6Z&dib=eyJ2IjoiMSJ9.ugoRDgk6CPUHAO-vuB2wI78pO390UDdb6RIU-aabDt5oU4otZYiGUnN6i_3bTOJjtcS38F6V6MAp5orniGxaedyNOGAYlDK7d99c9ucqP2kacaNCFHiHGfY9UEeOjwzul9iF8cSC9UucU8Gs5GLNy7FQ0V8OzIpdhNU--RElP62tW8GL2hHkxWv1CovRPUE2ikPC0MLd9pFvg58mnuxLOGLRhpXKRp64sVad5ICo7pE.-xmc_AxVrBglQX_RvSgqSLCabFYrz8FXomxgbbeGO4o&dib_tag=se&keywords=gaming+laptops&qid=1789819887&sprefix=%2Caps%2C392&sr=8-21&xpid=MMcXVFo9VX50C
A15: msi Vector A18 HX 18" 240Hz QHD+ Gaming Laptop: AMD Ryzen 9-9955HX, NVIDIA Geforce RTX 5080, 32GB DDR5, 1TB NVMe SSD, Type C, Wi-Fi 7, Win 11 Home: Cosmo Gray A9WIG-065US | B15: msi | C15: Vector A18 HX A9WIG-065US | D15: =IF(OR(ISNUMBER(SEARCH("charger",A15)),ISNUMBER(SEARCH("cable",A15)),ISNUMBER(SEARCH("adapter",A15)),ISNUMBER(SEARCH("dock",A15)),ISNUMBER(SEARCH("replacement",A15))),"Accessory / Other",IF(OR(J15="Dedicated",ISNUMBER(SEARCH("rtx",J15&" "&K15)),ISNUMBER(SEARCH("gtx",J15&" "&K15)),ISNUMBER(SEARCH("rx 5",J15&" "&K15)),ISNUMBER(SEARCH("rx 6",J15&" "&K15)),ISNUMBER(SEARCH("rx 7",J15&" "&K15)),ISNUMBER(SEARCH("rx 8",J15&" "&K15)),ISNUMBER(SEARCH("rx 9",J15&" "&K15)),AND(IFERROR(N15>=120,FALSE),ISNUMBER(SEARCH("gaming",A15&" "&C15)))),"Gaming",IF(OR(ISNUMBER(SEARCH("thinkpad",C15)),ISNUMBER(SEARCH("latitude",C15)),ISNUMBER(SEARCH("probook",C15)),ISNUMBER(SEARCH("elitebook",C15)),ISNUMBER(SEARCH("office",A15&" "&Q15)),ISNUMBER(SEARCH("business",A15&" "&Q15)),AND(ISNUMBER(SEARCH("windows 11 pro",I15)),J15="Integrated")),"Office / Business",IF(OR(ISNUMBER(SEARCH("creator",A15&" "&Q15)),ISNUMBER(SEARCH("studio",A15&" "&C15)),ISNUMBER(SEARCH("workstation",A15&" "&C15)),ISNUMBER(SEARCH("precision",A15&" "&C15)),ISNUMBER(SEARCH("zbook",A15&" "&C15))),"Creator / Professional","Normal Use")))) -> Gaming | E15: 18 | F15: Ryzen 9 | G15: 32 | H15: 1000 | I15: Windows 11 Home | J15: RTX 5080 | K15: NVIDIA Geforce RTX 5080 | L15: QHD | M15: QHD+ | N15: 240 | O15: Not Provided | P15: Gray | Q15: Backlit Keyboard | Fingerprint Reader | R15: Wi-Fi 7 | S15: 3.8 | T15: 27 | U15: 748369.73 | V15: 748369.73 | W15: =((V15-U15)/V15)*100 -> 0 | X15: =IF(W15>0,"Yes","No") -> No | Y15: 31830.78 | Z15: 29-09-2026 | AB15: https://m.media-amazon.com/images/I/71wEDLLi83L._AC_UY218_.jpg | AC15: https://www.amazon.com/MSI-Vector-240Hz-Gaming-Laptop/dp/B0DVDGRP1X/ref=sr_1_23?crid=3LC9VL11Q1Y6Z&dib=eyJ2IjoiMSJ9.ugoRDgk6CPUHAO-vuB2wI78pO390UDdb6RIU-aabDt5oU4otZYiGUnN6i_3bTOJjtcS38F6V6MAp5orniGxaedyNOGAYlDK7d99c9ucqP2kacaNCFHiHGfY9UEeOjwzul9iF8cSC9UucU8Gs5GLNy7FQ0V8OzIpdhNU--RElP62tW8GL2hHkxWv1CovRPUE2ikPC0MLd9pFvg58mnuxLOGLRhpXKRp64sVad5ICo7pE.-xmc_AxVrBglQX_RvSgqSLCabFYrz8FXomxgbbeGO4o&dib_tag=se&keywords=gaming+laptops&qid=1789819887&sprefix=%2Caps%2C392&sr=8-23&xpid=MMcXVFo9VX50C
A16: 18.5 Inch Gaming Laptop with 7000 mAh Battery,AMD Ryzen 7430U UP to 4.3GHZ | B16: Not Provided | C16: Not Provided | D16: =IF(OR(ISNUMBER(SEARCH("charger",A16)),ISNUMBER(SEARCH("cable",A16)),ISNUMBER(SEARCH("adapter",A16)),ISNUMBER(SEARCH("dock",A16)),ISNUMBER(SEARCH("replacement",A16))),"Accessory / Other",IF(OR(J16="Dedicated",ISNUMBER(SEARCH("rtx",J16&" "&K16)),ISNUMBER(SEARCH("gtx",J16&" "&K16)),ISNUMBER(SEARCH("rx 5",J16&" "&K16)),ISNUMBER(SEARCH("rx 6",J16&" "&K16)),ISNUMBER(SEARCH("rx 7",J16&" "&K16)),ISNUMBER(SEARCH("rx 8",J16&" "&K16)),ISNUMBER(SEARCH("rx 9",J16&" "&K16)),AND(IFERROR(N16>=120,FALSE),ISNUMBER(SEARCH("gaming",A16&" "&C16)))),"Gaming",IF(OR(ISNUMBER(SEARCH("thinkpad",C16)),ISNUMBER(SEARCH("latitude",C16)),ISNUMBER(SEARCH("probook",C16)),ISNUMBER(SEARCH("elitebook",C16)),ISNUMBER(SEARCH("office",A16&" "&Q16)),ISNUMBER(SEARCH("business",A16&" "&Q16)),AND(ISNUMBER(SEARCH("windows 11 pro",I16)),J16="Integrated")),"Office / Business",IF(OR(ISNUMBER(SEARCH("creator",A16&" "&Q16)),ISNUMBER(SEARCH("studio",A16&" "&C16)),ISNUMBER(SEARCH("workstation",A16&" "&C16)),ISNUMBER(SEARCH("precision",A16&" "&C16)),ISNUMBER(SEARCH("zbook",A16&" "&C16))),"Creator / Professional","Normal Use")))) -> Normal Use | E16: 18.5 | F16: AMD Ryzen 7430U UP to 4 | I16: Not Provided | J16: Not Provided | K16: Not Provided | L16: Not Provided | M16: Not Provided | O16: UP to 4.3GHZ | P16: Not Provided | Q16: 7000 mAh | R16: Not Provided | S16: 4.8 | T16: 18 | U16: 182655.55 | V16: 443477.23 | W16: =((V16-U16)/V16)*100 -> 58.812868 | X16: =IF(W16>0,"Yes","No") -> Yes | Y16: 21996.61 | Z16: 29-09-2026 | AB16: https://m.media-amazon.com/images/I/715V4VP-nfL._AC_UY218_.jpg | AC16: https://www.amazon.com/sspa/click?ie=UTF8&spc=MToxMDM2NjU2NzcwMzIwNDU2OjE3ODk4MTk4ODc6c3BfbXRmOjMwMTUzMzk0OTYyOTkwMjo6MDo6&url=%2FGaming-Laptop-Battery-Ryzen-4-3GHZ%2Fdp%2FB0HF3J55CY%2Fref%3Dsr_1_27_sspa%3Fcrid%3D3LC9VL11Q1Y6Z%26dib%3DeyJ2IjoiMSJ9.ugoRDgk6CPUHAO-vuB2wI78pO390UDdb6RIU-aabDt5oU4otZYiGUnN6i_3bTOJjtcS38F6V6MAp5orniGxaedyNOGAYlDK7d99c9ucqP2kacaNCFHiHGfY9UEeOjwzul9iF8cSC9UucU8Gs5GLNy7FQ0V8OzIpdhNU--RElP62tW8GL2hHkxWv1CovRPUE2ikPC0MLd9pFvg58mnuxLOGLRhpXKRp64sVad5ICo7pE.-xmc_AxVrBglQX_RvSgqSLCabFYrz8FXomxgbbeGO4o%26dib_tag%3Dse%26keywords%3Dgaming%2Blaptops%26qid%3D1789819887%26sprefix%3D%252Caps%252C392%26sr%3D8-27-spons%26xpid%3DMMcXVFo9VX50C%26sp_csd%3Dd2lkZ2V0TmFtZT1zcF9tdGY%26psc%3D1
A17: dynabook Tecra A40-M 14" WUXGA Business Laptop, Intel Core Ultra 7 155U, 32GB DDR5, 1TB PCIe SSD, Windows 11 Pro, Wi-Fi 6E, Thunderbolt 4, 5MP AI Webcam, Fingerprint | B17: dynabook | C17: Tecra A40-M 14" WUXGA Business | D17: =IF(OR(ISNUMBER(SEARCH("charger",A17)),ISNUMBER(SEARCH("cable",A17)),ISNUMBER(SEARCH("adapter",A17)),ISNUMBER(SEARCH("dock",A17)),ISNUMBER(SEARCH("replacement",A17))),"Accessory / Other",IF(OR(J17="Dedicated",ISNUMBER(SEARCH("rtx",J17&" "&K17)),ISNUMBER(SEARCH("gtx",J17&" "&K17)),ISNUMBER(SEARCH("rx 5",J17&" "&K17)),ISNUMBER(SEARCH("rx 6",J17&" "&K17)),ISNUMBER(SEARCH("rx 7",J17&" "&K17)),ISNUMBER(SEARCH("rx 8",J17&" "&K17)),ISNUMBER(SEARCH("rx 9",J17&" "&K17)),AND(IFERROR(N17>=120,FALSE),ISNUMBER(SEARCH("gaming",A17&" "&C17)))),"Gaming",IF(OR(ISNUMBER(SEARCH("thinkpad",C17)),ISNUMBER(SEARCH("latitude",C17)),ISNUMBER(SEARCH("probook",C17)),ISNUMBER(SEARCH("elitebook",C17)),ISNUMBER(SEARCH("office",A17&" "&Q17)),ISNUMBER(SEARCH("business",A17&" "&Q17)),AND(ISNUMBER(SEARCH("windows 11 pro",I17)),J17="Integrated")),"Office / Business",IF(OR(ISNUMBER(SEARCH("creator",A17&" "&Q17)),ISNUMBER(SEARCH("studio",A17&" "&C17)),ISNUMBER(SEARCH("workstation",A17&" "&C17)),ISNUMBER(SEARCH("precision",A17&" "&C17)),ISNUMBER(SEARCH("zbook",A17&" "&C17))),"Creator / Professional","Normal Use")))) -> Office / Business | F17: Intel Core Ultra 7 155U | G17: 32 | H17: 32 | I17: Windows 11 Pro | J17: Not Provided | K17: Not Provided | L17: WUXGA | M17: WUXGA | O17: Not Provided | P17: Not Provided | Q17: Wi-Fi 6 | 5MP AI Webcam | DDR5 | R17: Wi-Fi 6E | Thunderbolt 4 | S17: 0 | T17: 0 | U17: 493094.32 | V17: 493094.32 | W17: =((V17-U17)/V17)*100 -> 0 | X17: =IF(W17>0,"Yes","No") -> No | Y17: 21115.19 | Z17: 29-09-2026 | AB17: https://m.media-amazon.com/images/I/61Qz-lvLf0L._AC_UY218_.jpg | AC17: https://www.amazon.com/sspa/click?ie=UTF8&spc=MToxMDM2NjU2NzcwMzIwNDU2OjE3ODk4MTk4ODc6c3BfbXRmOjMwMTQ4NjQyMTcwNTkwMjo6MDo6&url=%2Fdynabook-A40-M-Business-Thunderbolt-Fingerprint%2Fdp%2FB0GT8T34V8%2Fref%3Dsr_1_28_sspa%3Fcrid%3D3LC9VL11Q1Y6Z%26dib%3DeyJ2IjoiMSJ9.ugoRDgk6CPUHAO-vuB2wI78pO390UDdb6RIU-aabDt5oU4otZYiGUnN6i_3bTOJjtcS38F6V6MAp5orniGxaedyNOGAYlDK7d99c9ucqP2kacaNCFHiHGfY9UEeOjwzul9iF8cSC9UucU8Gs5GLNy7FQ0V8OzIpdhNU--RElP62tW8GL2hHkxWv1CovRPUE2ikPC0MLd9pFvg58mnuxLOGLRhpXKRp64sVad5ICo7pE.-xmc_AxVrBglQX_RvSgqSLCabFYrz8FXomxgbbeGO4o%26dib_tag%3Dse%26keywords%3Dgaming%2Blaptops%26qid%3D1789819887%26sprefix%3D%252Caps%252C392%26sr%3D8-28-spons%26xpid%3DMMcXVFo9VX50C%26sp_csd%3Dd2lkZ2V0TmFtZT1zcF9tdGY%26psc%3D1
A18: Gaming Laptop with AMD Ryzen 7 H255 (up to 4.9GHz),24GB DDR5 512GB NVMe SSD | B18: MALLRACE | C18: S16 | D18: =IF(OR(ISNUMBER(SEARCH("charger",A18)),ISNUMBER(SEARCH("cable",A18)),ISNUMBER(SEARCH("adapter",A18)),ISNUMBER(SEARCH("dock",A18)),ISNUMBER(SEARCH("replacement",A18))),"Accessory / Other",IF(OR(J18="Dedicated",ISNUMBER(SEARCH("rtx",J18&" "&K18)),ISNUMBER(SEARCH("gtx",J18&" "&K18)),ISNUMBER(SEARCH("rx 5",J18&" "&K18)),ISNUMBER(SEARCH("rx 6",J18&" "&K18)),ISNUMBER(SEARCH("rx 7",J18&" "&K18)),ISNUMBER(SEARCH("rx 8",J18&" "&K18)),ISNUMBER(SEARCH("rx 9",J18&" "&K18)),AND(IFERROR(N18>=120,FALSE),ISNUMBER(SEARCH("gaming",A18&" "&C18)))),"Gaming",IF(OR(ISNUMBER(SEARCH("thinkpad",C18)),ISNUMBER(SEARCH("latitude",C18)),ISNUMBER(SEARCH("probook",C18)),ISNUMBER(SEARCH("elitebook",C18)),ISNUMBER(SEARCH("office",A18&" "&Q18)),ISNUMBER(SEARCH("business",A18&" "&Q18)),AND(ISNUMBER(SEARCH("windows 11 pro",I18)),J18="Integrated")),"Office / Business",IF(OR(ISNUMBER(SEARCH("creator",A18&" "&Q18)),ISNUMBER(SEARCH("studio",A18&" "&C18)),ISNUMBER(SEARCH("workstation",A18&" "&C18)),ISNUMBER(SEARCH("precision",A18&" "&C18)),ISNUMBER(SEARCH("zbook",A18&" "&C18))),"Creator / Professional","Normal Use")))) -> Office / Business | E18: 16 | F18: AMD Ryzen 7 | G18: 24 | H18: 512 | I18: Windows 11 Pro | J18: Integrated | K18: Not Provided | L18: Not Provided | M18: Not Provided | O18: up to 4.9GHz | P18: Lead Gray | Q18: 24GB DDR5 512GB SSD | AMD Radeon 780M | AMD Ryzen7 H255 4.9GHz | Backlit Keyboard | HDMI 2.0 | R18: Not Provided | S18: 4.4 | T18: 41 | U18: 191247.98 | V18: 221737.23 | W18: =((V18-U18)/V18)*100 -> 13.750172 | X18: =IF(W18>0,"Yes","No") -> Yes | Y18: 19382.85 | AB18: https://m.media-amazon.com/images/I/71jdw6czCML._AC_UY218_.jpg | AC18: https://www.amazon.com/Gaming-Laptop-Ryzen-4-9GHz-512GB/dp/B0H4GDCQJF/ref=sr_1_29?crid=3LC9VL11Q1Y6Z&dib=eyJ2IjoiMSJ9.ugoRDgk6CPUHAO-vuB2wI78pO390UDdb6RIU-aabDt5oU4otZYiGUnN6i_3bTOJjtcS38F6V6MAp5orniGxaedyNOGAYlDK7d99c9ucqP2kacaNCFHiHGfY9UEeOjwzul9iF8cSC9UucU8Gs5GLNy7FQ0V8OzIpdhNU--RElP62tW8GL2hHkxWv1CovRPUE2ikPC0MLd9pFvg58mnuxLOGLRhpXKRp64sVad5ICo7pE.-xmc_AxVrBglQX_RvSgqSLCabFYrz8FXomxgbbeGO4o&dib_tag=se&keywords=gaming+laptops&qid=1789819887&sprefix=%2Caps%2C392&sr=8-29&xpid=MMcXVFo9VX50C
A19: Gaming Laptop 2026,Office & Windows 11 Pro Laptops with 16GB 512GB SSD | B19: CHIFUYOU | C19: Intel Core i7-7600U 16GB +1TB SSD | D19: =IF(OR(ISNUMBER(SEARCH("charger",A19)),ISNUMBER(SEARCH("cable",A19)),ISNUMBER(SEARCH("adapter",A19)),ISNUMBER(SEARCH("dock",A19)),ISNUMBER(SEARCH("replacement",A19))),"Accessory / Other",IF(OR(J19="Dedicated",ISNUMBER(SEARCH("rtx",J19&" "&K19)),ISNUMBER(SEARCH("gtx",J19&" "&K19)),ISNUMBER(SEARCH("rx 5",J19&" "&K19)),ISNUMBER(SEARCH("rx 6",J19&" "&K19)),ISNUMBER(SEARCH("rx 7",J19&" "&K19)),ISNUMBER(SEARCH("rx 8",J19&" "&K19)),ISNUMBER(SEARCH("rx 9",J19&" "&K19)),AND(IFERROR(N19>=120,FALSE),ISNUMBER(SEARCH("gaming",A19&" "&C19)))),"Gaming",IF(OR(ISNUMBER(SEARCH("thinkpad",C19)),ISNUMBER(SEARCH("latitude",C19)),ISNUMBER(SEARCH("probook",C19)),ISNUMBER(SEARCH("elitebook",C19)),ISNUMBER(SEARCH("office",A19&" "&Q19)),ISNUMBER(SEARCH("business",A19&" "&Q19)),AND(ISNUMBER(SEARCH("windows 11 pro",I19)),J19="Integrated")),"Office / Business",IF(OR(ISNUMBER(SEARCH("creator",A19&" "&Q19)),ISNUMBER(SEARCH("studio",A19&" "&C19)),ISNUMBER(SEARCH("workstation",A19&" "&C19)),ISNUMBER(SEARCH("precision",A19&" "&C19)),ISNUMBER(SEARCH("zbook",A19&" "&C19))),"Creator / Professional","Normal Use")))) -> Office / Business | E19: 15.6 | F19: Core i7 | G19: 16 | H19: 512 | I19: Windows 11 Pro | J19: Integrated | K19: Not Provided | L19: Not Provided | M19: Not Provided | O19: Not Provided | P19: Gray | Q19: Anti Glare Coating | Backlit Keyboard | HD Audio | Lightweight | Numeric Keypad | R19: Not Provided | S19: 3.8 | T19: 56 | U19: 110867.23 | V19: 124725.98 | W19: =((V19-U19)/V19)*100 -> 11.111358 | X19: =IF(W19>0,"Yes","No") -> Yes | Y19: 14748.48 | Z19: 29-09-2026 | AB19: https://m.media-amazon.com/images/I/711XuaEUR5L._AC_UY218_.jpg | AC19: https://www.amazon.com/Gaming-Laptop-Office-Windows-Laptops/dp/B0H947WPTC/ref=sr_1_33?crid=3LC9VL11Q1Y6Z&dib=eyJ2IjoiMSJ9.ugoRDgk6CPUHAO-vuB2wI78pO390UDdb6RIU-aabDt5oU4otZYiGUnN6i_3bTOJjtcS38F6V6MAp5orniGxaedyNOGAYlDK7d99c9ucqP2kacaNCFHiHGfY9UEeOjwzul9iF8cSC9UucU8Gs5GLNy7FQ0V8OzIpdhNU--RElP62tW8GL2hHkxWv1CovRPUE2ikPC0MLd9pFvg58mnuxLOGLRhpXKRp64sVad5ICo7pE.-xmc_AxVrBglQX_RvSgqSLCabFYrz8FXomxgbbeGO4o&dib_tag=se&keywords=gaming+laptops&qid=1789819887&sprefix=%2Caps%2C392&sr=8-33&xpid=MMcXVFo9VX50C
A20: Lenovo IdeaPad Pro 5-2025 - 16" OLED 2880 x 1800 120Hz Display - 16GB - 1 TB Storage - Ryzen AI 7 350 - NVIDIA GeForce RTX5050 - Windows 11 Home - Luna Grey | B20: Lenovo | C20: IdeaPad Pro 5 | D20: =IF(OR(ISNUMBER(SEARCH("charger",A20)),ISNUMBER(SEARCH("cable",A20)),ISNUMBER(SEARCH("adapter",A20)),ISNUMBER(SEARCH("dock",A20)),ISNUMBER(SEARCH("replacement",A20))),"Accessory / Other",IF(OR(J20="Dedicated",ISNUMBER(SEARCH("rtx",J20&" "&K20)),ISNUMBER(SEARCH("gtx",J20&" "&K20)),ISNUMBER(SEARCH("rx 5",J20&" "&K20)),ISNUMBER(SEARCH("rx 6",J20&" "&K20)),ISNUMBER(SEARCH("rx 7",J20&" "&K20)),ISNUMBER(SEARCH("rx 8",J20&" "&K20)),ISNUMBER(SEARCH("rx 9",J20&" "&K20)),AND(IFERROR(N20>=120,FALSE),ISNUMBER(SEARCH("gaming",A20&" "&C20)))),"Gaming",IF(OR(ISNUMBER(SEARCH("thinkpad",C20)),ISNUMBER(SEARCH("latitude",C20)),ISNUMBER(SEARCH("probook",C20)),ISNUMBER(SEARCH("elitebook",C20)),ISNUMBER(SEARCH("office",A20&" "&Q20)),ISNUMBER(SEARCH("business",A20&" "&Q20)),AND(ISNUMBER(SEARCH("windows 11 pro",I20)),J20="Integrated")),"Office / Business",IF(OR(ISNUMBER(SEARCH("creator",A20&" "&Q20)),ISNUMBER(SEARCH("studio",A20&" "&C20)),ISNUMBER(SEARCH("workstation",A20&" "&C20)),ISNUMBER(SEARCH("precision",A20&" "&C20)),ISNUMBER(SEARCH("zbook",A20&" "&C20))),"Creator / Professional","Normal Use")))) -> Gaming | E20: 16 | F20: Ryzen 7 | G20: 16 | H20: 1000 | I20: Windows 11 Home | J20: Dedicated | K20: NVIDIA GeForce RTX5050 | L20: 2880 x 1800 | M20: OLED | N20: 120 | O20: Not Provided | P20: Luna Grey | Q20: OLED 120Hz Display | R20: Not Provided | S20: 3.6 | T20: 30 | U20: 304615.32 | V20: 304615.32 | W20: =((V20-U20)/V20)*100 -> 0 | X20: =IF(W20>0,"Yes","No") -> No | Y20: 27448.64 | Z20: 29-09-2026 | AB20: https://m.media-amazon.com/images/I/71kyi296+RL._AC_UY218_.jpg | AC20: https://www.amazon.com/Lenovo-IdeaPad-Pro-5-2025-Display/dp/B0DTBFNLCJ/ref=sr_1_34?crid=3LC9VL11Q1Y6Z&dib=eyJ2IjoiMSJ9.ugoRDgk6CPUHAO-vuB2wI78pO390UDdb6RIU-aabDt5oU4otZYiGUnN6i_3bTOJjtcS38F6V6MAp5orniGxaedyNOGAYlDK7d99c9ucqP2kacaNCFHiHGfY9UEeOjwzul9iF8cSC9UucU8Gs5GLNy7FQ0V8OzIpdhNU--RElP62tW8GL2hHkxWv1CovRPUE2ikPC0MLd9pFvg58mnuxLOGLRhpXKRp64sVad5ICo7pE.-xmc_AxVrBglQX_RvSgqSLCabFYrz8FXomxgbbeGO4o&dib_tag=se&keywords=gaming+laptops&qid=1789819887&sprefix=%2Caps%2C392&sr=8-34&xpid=MMcXVFo9VX50C
A21: Lenovo Legion 5i – Gaming Laptop - Intel® Core™ i7-14700HX - 15" 2.5K WQXGA PureSight OLED Display–165Hz Refresh Rate–NVIDIA® GeForce RTX™ 5070 – 16 GB – 1 TB Storage – 3 Months of PC GamePass | B21: Lenovo | C21: Legion 5i | D21: =IF(OR(ISNUMBER(SEARCH("charger",A21)),ISNUMBER(SEARCH("cable",A21)),ISNUMBER(SEARCH("adapter",A21)),ISNUMBER(SEARCH("dock",A21)),ISNUMBER(SEARCH("replacement",A21))),"Accessory / Other",IF(OR(J21="Dedicated",ISNUMBER(SEARCH("rtx",J21&" "&K21)),ISNUMBER(SEARCH("gtx",J21&" "&K21)),ISNUMBER(SEARCH("rx 5",J21&" "&K21)),ISNUMBER(SEARCH("rx 6",J21&" "&K21)),ISNUMBER(SEARCH("rx 7",J21&" "&K21)),ISNUMBER(SEARCH("rx 8",J21&" "&K21)),ISNUMBER(SEARCH("rx 9",J21&" "&K21)),AND(IFERROR(N21>=120,FALSE),ISNUMBER(SEARCH("gaming",A21&" "&C21)))),"Gaming",IF(OR(ISNUMBER(SEARCH("thinkpad",C21)),ISNUMBER(SEARCH("latitude",C21)),ISNUMBER(SEARCH("probook",C21)),ISNUMBER(SEARCH("elitebook",C21)),ISNUMBER(SEARCH("office",A21&" "&Q21)),ISNUMBER(SEARCH("business",A21&" "&Q21)),AND(ISNUMBER(SEARCH("windows 11 pro",I21)),J21="Integrated")),"Office / Business",IF(OR(ISNUMBER(SEARCH("creator",A21&" "&Q21)),ISNUMBER(SEARCH("studio",A21&" "&C21)),ISNUMBER(SEARCH("workstation",A21&" "&C21)),ISNUMBER(SEARCH("precision",A21&" "&C21)),ISNUMBER(SEARCH("zbook",A21&" "&C21))),"Creator / Professional","Normal Use")))) -> Gaming | E21: 15.1 | F21: Core i7 | G21: 16 | H21: 1000 | I21: Windows 11 Home | J21: Dedicated | K21: NVIDIA GeForce RTX 5070 | L21: 2.5K | M21: WQXGA | N21: 165 | O21: Not Provided | P21: Eclipse Black | Q21: Backlit Keyboard | HD Audio | Wifi | R21: Not Provided | S21: 4.3 | T21: 97 | U21: 527821.58 | V21: 527821.58 | W21: =((V21-U21)/V21)*100 -> 0 | X21: =IF(W21>0,"Yes","No") -> No | Y21: 21112.42 | Z21: 29-09-2026 | AB21: https://m.media-amazon.com/images/I/81fcgC6vlsL._AC_UY218_.jpg | AC21: https://www.amazon.com/Lenovo-Legion-i7-14700HX-Display-165Hz-Rate-NVIDIA%C2%AE/dp/B0F6NRYPPG/ref=sr_1_35?crid=3LC9VL11Q1Y6Z&dib=eyJ2IjoiMSJ9.ugoRDgk6CPUHAO-vuB2wI78pO390UDdb6RIU-aabDt5oU4otZYiGUnN6i_3bTOJjtcS38F6V6MAp5orniGxaedyNOGAYlDK7d99c9ucqP2kacaNCFHiHGfY9UEeOjwzul9iF8cSC9UucU8Gs5GLNy7FQ0V8OzIpdhNU--RElP62tW8GL2hHkxWv1CovRPUE2ikPC0MLd9pFvg58mnuxLOGLRhpXKRp64sVad5ICo7pE.-xmc_AxVrBglQX_RvSgqSLCabFYrz8FXomxgbbeGO4o&dib_tag=se&keywords=gaming+laptops&qid=1789819887&sprefix=%2Caps%2C392&sr=8-35&xpid=MMcXVFo9VX50C
A22: msi Katana 15 HX 15.6" 165Hz QHD+ Gaming Laptop: Intel Core i9-14900HX, NVIDIA Geforce RTX 5070, 32GB DDR5, 1TB NVMe SSD, RGB Keyboard, Win 11 Home: Black B14WGK-016US | B22: msi | C22: Katana 15 HX B14WGK-016US | D22: =IF(OR(ISNUMBER(SEARCH("charger",A22)),ISNUMBER(SEARCH("cable",A22)),ISNUMBER(SEARCH("adapter",A22)),ISNUMBER(SEARCH("dock",A22)),ISNUMBER(SEARCH("replacement",A22))),"Accessory / Other",IF(OR(J22="Dedicated",ISNUMBER(SEARCH("rtx",J22&" "&K22)),ISNUMBER(SEARCH("gtx",J22&" "&K22)),ISNUMBER(SEARCH("rx 5",J22&" "&K22)),ISNUMBER(SEARCH("rx 6",J22&" "&K22)),ISNUMBER(SEARCH("rx 7",J22&" "&K22)),ISNUMBER(SEARCH("rx 8",J22&" "&K22)),ISNUMBER(SEARCH("rx 9",J22&" "&K22)),AND(IFERROR(N22>=120,FALSE),ISNUMBER(SEARCH("gaming",A22&" "&C22)))),"Gaming",IF(OR(ISNUMBER(SEARCH("thinkpad",C22)),ISNUMBER(SEARCH("latitude",C22)),ISNUMBER(SEARCH("probook",C22)),ISNUMBER(SEARCH("elitebook",C22)),ISNUMBER(SEARCH("office",A22&" "&Q22)),ISNUMBER(SEARCH("business",A22&" "&Q22)),AND(ISNUMBER(SEARCH("windows 11 pro",I22)),J22="Integrated")),"Office / Business",IF(OR(ISNUMBER(SEARCH("creator",A22&" "&Q22)),ISNUMBER(SEARCH("studio",A22&" "&C22)),ISNUMBER(SEARCH("workstation",A22&" "&C22)),ISNUMBER(SEARCH("precision",A22&" "&C22)),ISNUMBER(SEARCH("zbook",A22&" "&C22))),"Creator / Professional","Normal Use")))) -> Gaming | E22: 15.6 | F22: Core i9 | G22: 32 | H22: 1000 | I22: Windows 11 Home | J22: RTX 5070 | K22: NVIDIA Geforce RTX 5070 | L22: QHD | M22: QHD+ | N22: 165 | O22: Not Provided | P22: Black | Q22: Backlit Keyboard | HD Audio | R22: Not Provided | S22: 4 | T22: 348 | U22: 629251 | V22: 629251 | W22: =((V22-U22)/V22)*100 -> 0 | X22: =IF(W22>0,"Yes","No") -> No | Y22: 24225.1 | Z22: 29-09-2026 | AB22: https://m.media-amazon.com/images/I/71TvKdAmIjL._AC_UY218_.jpg | AC22: https://www.amazon.com/Katana-15-6-165Hz-Gaming-Laptop/dp/B0DZFVBQLK/ref=sr_1_36?crid=3LC9VL11Q1Y6Z&dib=eyJ2IjoiMSJ9.ugoRDgk6CPUHAO-vuB2wI78pO390UDdb6RIU-aabDt5oU4otZYiGUnN6i_3bTOJjtcS38F6V6MAp5orniGxaedyNOGAYlDK7d99c9ucqP2kacaNCFHiHGfY9UEeOjwzul9iF8cSC9UucU8Gs5GLNy7FQ0V8OzIpdhNU--RElP62tW8GL2hHkxWv1CovRPUE2ikPC0MLd9pFvg58mnuxLOGLRhpXKRp64sVad5ICo7pE.-xmc_AxVrBglQX_RvSgqSLCabFYrz8FXomxgbbeGO4o&dib_tag=se&keywords=gaming+laptops&qid=1789819887&sprefix=%2Caps%2C392&sr=8-36&xpid=MMcXVFo9VX50C
A23: Lenovo Legion LOQ AI-Powered Gaming Laptop - Intel Core i7-13650HX, 15.6" FHD IPS 144Hz Display, GeForce RTX 5050, 16GB , 1TB Storage, G-Sync, Luna Grey | B23: Lenovo | C23: Legion LOQ AI-Powered | D23: =IF(OR(ISNUMBER(SEARCH("charger",A23)),ISNUMBER(SEARCH("cable",A23)),ISNUMBER(SEARCH("adapter",A23)),ISNUMBER(SEARCH("dock",A23)),ISNUMBER(SEARCH("replacement",A23))),"Accessory / Other",IF(OR(J23="Dedicated",ISNUMBER(SEARCH("rtx",J23&" "&K23)),ISNUMBER(SEARCH("gtx",J23&" "&K23)),ISNUMBER(SEARCH("rx 5",J23&" "&K23)),ISNUMBER(SEARCH("rx 6",J23&" "&K23)),ISNUMBER(SEARCH("rx 7",J23&" "&K23)),ISNUMBER(SEARCH("rx 8",J23&" "&K23)),ISNUMBER(SEARCH("rx 9",J23&" "&K23)),AND(IFERROR(N23>=120,FALSE),ISNUMBER(SEARCH("gaming",A23&" "&C23)))),"Gaming",IF(OR(ISNUMBER(SEARCH("thinkpad",C23)),ISNUMBER(SEARCH("latitude",C23)),ISNUMBER(SEARCH("probook",C23)),ISNUMBER(SEARCH("elitebook",C23)),ISNUMBER(SEARCH("office",A23&" "&Q23)),ISNUMBER(SEARCH("business",A23&" "&Q23)),AND(ISNUMBER(SEARCH("windows 11 pro",I23)),J23="Integrated")),"Office / Business",IF(OR(ISNUMBER(SEARCH("creator",A23&" "&Q23)),ISNUMBER(SEARCH("studio",A23&" "&C23)),ISNUMBER(SEARCH("workstation",A23&" "&C23)),ISNUMBER(SEARCH("precision",A23&" "&C23)),ISNUMBER(SEARCH("zbook",A23&" "&C23))),"Creator / Professional","Normal Use")))) -> Gaming | F23: Intel Core i7-13650HX | G23: 16 | H23: 16 | I23: Not Provided | J23: GeForce RTX 5050 | K23: GeForce RTX 5050 | L23: FHD | M23: FHD | N23: 144 | O23: Not Provided | P23: Grey | Q23: G-Sync | IPS | R23: Not Provided | S23: 4.3 | T23: 108 | U23: 422689.1 | V23: 422689.1 | W23: =((V23-U23)/V23)*100 -> 0 | X23: =IF(W23>0,"Yes","No") -> No | Y23: 22426.23 | Z23: 29-09-2026 | AB23: https://m.media-amazon.com/images/I/813oYBqM4GL._AC_UY218_.jpg | AC23: https://www.amazon.com/sspa/click?ie=UTF8&spc=MToxMDM2NjU2NzcwMzIwNDU2OjE3ODk4MTk4ODc6c3BfYnRmOjMwMTIzMDcxMjQ4MDYwMjo6MDo6&url=%2FLenovo-Legion-AI-Powered-Gaming-Laptop%2Fdp%2FB0FY77GFRN%2Fref%3Dsr_1_37_sspa%3Fcrid%3D3LC9VL11Q1Y6Z%26dib%3DeyJ2IjoiMSJ9.ugoRDgk6CPUHAO-vuB2wI78pO390UDdb6RIU-aabDt5oU4otZYiGUnN6i_3bTOJjtcS38F6V6MAp5orniGxaedyNOGAYlDK7d99c9ucqP2kacaNCFHiHGfY9UEeOjwzul9iF8cSC9UucU8Gs5GLNy7FQ0V8OzIpdhNU--RElP62tW8GL2hHkxWv1CovRPUE2ikPC0MLd9pFvg58mnuxLOGLRhpXKRp64sVad5ICo7pE.-xmc_AxVrBglQX_RvSgqSLCabFYrz8FXomxgbbeGO4o%26dib_tag%3Dse%26keywords%3Dgaming%2Blaptops%26qid%3D1789819887%26sprefix%3D%252Caps%252C392%26sr%3D8-37-spons%26xpid%3DMMcXVFo9VX50C%26sp_csd%3Dd2lkZ2V0TmFtZT1zcF9idGY%26psc%3D1
A24: Lenovo Legion 5i – Gaming Laptop - Intel® Core™ i7-14700HX - 15" 2.5K WQXGA PureSight OLED Display–165Hz Refresh Rate–NVIDIA® GeForce RTX™ 5070 – 16 GB – 1 TB Storage – 3 Months of PC GamePass | B24: Lenovo | C24: Legion 5i – | D24: =IF(OR(ISNUMBER(SEARCH("charger",A24)),ISNUMBER(SEARCH("cable",A24)),ISNUMBER(SEARCH("adapter",A24)),ISNUMBER(SEARCH("dock",A24)),ISNUMBER(SEARCH("replacement",A24))),"Accessory / Other",IF(OR(J24="Dedicated",ISNUMBER(SEARCH("rtx",J24&" "&K24)),ISNUMBER(SEARCH("gtx",J24&" "&K24)),ISNUMBER(SEARCH("rx 5",J24&" "&K24)),ISNUMBER(SEARCH("rx 6",J24&" "&K24)),ISNUMBER(SEARCH("rx 7",J24&" "&K24)),ISNUMBER(SEARCH("rx 8",J24&" "&K24)),ISNUMBER(SEARCH("rx 9",J24&" "&K24)),AND(IFERROR(N24>=120,FALSE),ISNUMBER(SEARCH("gaming",A24&" "&C24)))),"Gaming",IF(OR(ISNUMBER(SEARCH("thinkpad",C24)),ISNUMBER(SEARCH("latitude",C24)),ISNUMBER(SEARCH("probook",C24)),ISNUMBER(SEARCH("elitebook",C24)),ISNUMBER(SEARCH("office",A24&" "&Q24)),ISNUMBER(SEARCH("business",A24&" "&Q24)),AND(ISNUMBER(SEARCH("windows 11 pro",I24)),J24="Integrated")),"Office / Business",IF(OR(ISNUMBER(SEARCH("creator",A24&" "&Q24)),ISNUMBER(SEARCH("studio",A24&" "&C24)),ISNUMBER(SEARCH("workstation",A24&" "&C24)),ISNUMBER(SEARCH("precision",A24&" "&C24)),ISNUMBER(SEARCH("zbook",A24&" "&C24))),"Creator / Professional","Normal Use")))) -> Gaming | F24: Intel Core i7-14700HX - 15 | G24: 16 | H24: 16 | I24: Not Provided | J24: NVIDIA GeForce RTX 5070 | K24: NVIDIA GeForce RTX 5070 | L24: 2.5K | M24: WQXGA | N24: 165 | O24: Not Provided | P24: Not Provided | Q24: OLED | R24: Not Provided | S24: 4.3 | T24: 97 | U24: 527821.58 | V24: 527821.58 | W24: =((V24-U24)/V24)*100 -> 0 | X24: =IF(W24>0,"Yes","No") -> No | Y24: 21112.42 | Z24: 29-09-2026 | AB24: https://m.media-amazon.com/images/I/81fcgC6vlsL._AC_UY218_.jpg | AC24: https://www.amazon.com/sspa/click?ie=UTF8&spc=MToxMDM2NjU2NzcwMzIwNDU2OjE3ODk4MTk4ODc6c3BfYnRmOjMwMTIyOTg3NDYxMjEwMjo6MDo6&url=%2FLenovo-Legion-i7-14700HX-Display-165Hz-Rate-NVIDIA%25C2%25AE%2Fdp%2FB0F6NRYPPG%2Fref%3Dsr_1_38_sspa%3Fcrid%3D3LC9VL11Q1Y6Z%26dib%3DeyJ2IjoiMSJ9.ugoRDgk6CPUHAO-vuB2wI78pO390UDdb6RIU-aabDt5oU4otZYiGUnN6i_3bTOJjtcS38F6V6MAp5orniGxaedyNOGAYlDK7d99c9ucqP2kacaNCFHiHGfY9UEeOjwzul9iF8cSC9UucU8Gs5GLNy7FQ0V8OzIpdhNU--RElP62tW8GL2hHkxWv1CovRPUE2ikPC0MLd9pFvg58mnuxLOGLRhpXKRp64sVad5ICo7pE.-xmc_AxVrBglQX_RvSgqSLCabFYrz8FXomxgbbeGO4o%26dib_tag%3Dse%26keywords%3Dgaming%2Blaptops%26qid%3D1789819887%26sprefix%3D%252Caps%252C392%26sr%3D8-38-spons%26xpid%3DMMcXVFo9VX50C%26sp_csd%3Dd2lkZ2V0TmFtZT1zcF9idGY%26psc%3D1
B25: Not Provided | C25: Not Provided | D25: =IF(OR(ISNUMBER(SEARCH("charger",A25)),ISNUMBER(SEARCH("cable",A25)),ISNUMBER(SEARCH("adapter",A25)),ISNUMBER(SEARCH("dock",A25)),ISNUMBER(SEARCH("replacement",A25))),"Accessory / Other",IF(OR(J25="Dedicated",ISNUMBER(SEARCH("rtx",J25&" "&K25)),ISNUMBER(SEARCH("gtx",J25&" "&K25)),ISNUMBER(SEARCH("rx 5",J25&" "&K25)),ISNUMBER(SEARCH("rx 6",J25&" "&K25)),ISNUMBER(SEARCH("rx 7",J25&" "&K25)),ISNUMBER(SEARCH("rx 8",J25&" "&K25)),ISNUMBER(SEARCH("rx 9",J25&" "&K25)),AND(IFERROR(N25>=120,FALSE),ISNUMBER(SEARCH("gaming",A25&" "&C25)))),"Gaming",IF(OR(ISNUMBER(SEARCH("thinkpad",C25)),ISNUMBER(SEARCH("latitude",C25)),ISNUMBER(SEARCH("probook",C25)),ISNUMBER(SEARCH("elitebook",C25)),ISNUMBER(SEARCH("office",A25&" "&Q25)),ISNUMBER(SEARCH("business",A25&" "&Q25)),AND(ISNUMBER(SEARCH("windows 11 pro",I25)),J25="Integrated")),"Office / Business",IF(OR(ISNUMBER(SEARCH("creator",A25&" "&Q25)),ISNUMBER(SEARCH("studio",A25&" "&C25)),ISNUMBER(SEARCH("workstation",A25&" "&C25)),ISNUMBER(SEARCH("precision",A25&" "&C25)),ISNUMBER(SEARCH("zbook",A25&" "&C25))),"Creator / Professional","Normal Use")))) -> Normal Use | F25: Not Provided | I25: Not Provided | J25: Not Provided | K25: Not Provided | L25: Not Provided | M25: Not Provided | O25: Not Provided | P25: Not Provided | R25: Not Provided | S25: 4.3 | T25: 97 | U25: 527821.58 | V25: 221737.23 | W25: =((V25-U25)/V25)*100 -> -138.03922 | X25: =IF(W25>0,"Yes","No") -> No | Y25: 21112.42 | Z25: 29-09-2026 | AC25: https://www.amazon.com/sspa/click?ie=UTF8&spc=MToxODI5NDQwODUwMjE2MDg4OjE3ODk4MTk4ODc6c3Bfc2VhcmNoX3RoZW1hdGljX2J0ZjozMDEyMjk4NzQ2MTIxMDI6OjA6Og&url=%2FLenovo-Legion-i7-14700HX-Display-165Hz-Rate-NVIDIA%25C2%25AE%2Fdp%2FB0F6NRYPPG%2Fref%3Dsxbs_pa_sp_search_thematic_btf_sspa%3Fcontent-id%3Damzn1.sym.265ca31e-ac46-48b3-bd6c-07361db7a8ba%253Aamzn1.sym.265ca31e-ac46-48b3-bd6c-07361db7a8ba%26crid%3D3LC9VL11Q1Y6Z%26cv_ct_cx%3Dgaming%2Blaptops%26keywords%3Dgaming%2Blaptops%26pd_rd_i%3DB0F6NRYPPG%26pd_rd_r%3Da7b5e169-358b-45a7-9b16-1af917f71ab6%26pd_rd_w%3DU7lOp%26pd_rd_wg%3DMGfGM%26pf_rd_p%3D265ca31e-ac46-48b3-bd6c-07361db7a8ba%26pf_rd_r%3DWWP4F11RP569E3J953MC%26qid%3D1789819887%26sbo%3DRZvfv%252F%252FHxDF%252BO5021pAnSA%253D%253D%26sprefix%3D%252Caps%252C392%26sr%3D1-17-4c3ee5d8-c4ea-4c3c-8cf4-b8be2ae560c7-spons%26xpid%3DMMcXVFo9VX50C%26aref%3DzOVuCtIHuO%26sp_csd%3Dd2lkZ2V0TmFtZT1zcF9zZWFyY2hfdGhlbWF0aWNfYnRm%26psc%3D1&aref=zOVuCtIHuO
